Workbook

Sheet SS27
C1: 1 | D1: 2 | E1: 3 | F1: 4 | G1: 5 | H1: 6 | I1: 7 | J1: 8 | K1: 9 | L1: 10 | M1: 11 | N1: 12 | O1: 13 | P1: 14 | Q1: 15 | R1: 16 | S1: 17 | T1: 18 | U1: 19 | V1: 20 | W1: 21 | X1: 22 | Y1: 23 | Z1: 24 | AA1: 25 | AB1: 26 | AC1: 27
A2: Season | B2: Active | C2: Code | D2: Style | E2: Business Area | F2: Product Concept | G2: Category/Layer | H2: Collection Type | I2: Gender | J2: Proposed Drop Week | K2: Carry Over | L2: Update | M2: Target RRP | N2: Mark-up | O2: WP | P2: GM0% | Q2: Product Hierarchy | R2: Distribution Segmentation | S2: Main technology platform | T2: Secondary technology platform | U2: Style Comment | V2: ABS Customer | W2: STATUS | X2: LANDED COST SEK | Y2: REF_CODE | Z2: REF_NAME | AA2: Classification ABC | AB2: MOQ Style | AC2: MOQ Color | AD2: Check Pricing | AE2: Color Options | AF2: Collection | AG2: NEW MAPPING: Activity | AH2: PPT Collection / Activity (deck) | AI2: Category/Layer(V2) | AJ2: Silhouette | AK2: Category/Layer Subtype | AL2: Waterproof | AM2: Attribution Review | AN2: Franchise/Family
A3: SS27 | B3: TRUE | C3: 608172 | D3: Alert GTX Jacket Men | E3: Apparel | F3: OUT | G3: Shell | H3: Inline | I3: Men | K3: TRUE | L3: FALSE | M3: 3800 | N3: 2.1 | O3: 1809.52 | P3: 0.60502233 | Q3: Good | R3: SPECIALIST, GENERALIST MULTISPORT, INTERSPORT NORDIC, Lifestyle/DAY | S3: Gore-Tex | T3: None | W3: CO | X3: 714.72 | AA3: A | AB3: 1000 | AC3: 300 | AD3: 608172 | AE3: 4 | AF3: Outdoor | AG3: Day Hiking | AH3: Outdoor / Hiking [MATCH] | AI3: Shell | AJ3: Jacket | AK3: 2L | AL3: Y
A4: SS27 | B4: TRUE | C4: 608596 | D4: Alert GTX Jacket Men AF | E4: Apparel | F4: OUT | G4: Shell | H4: ABS Exclusive | I4: Men | K4: TRUE | L4: FALSE | M4: 3800 | N4: 2.1 | O4: 1809.52 | P4: 0.61495866 | Q4: Good | R4: ASIA | S4: Gore-Tex | T4: None | U4: Asia Fit version of Alert GTX Jacket Men 608172 | V4: ASIA | W4: CO | X4: 696.74 | AA4: C | AB4: 1000 | AC4: 300 | AD4: 608596 | AE4: 4 | AF4: Outdoor | AG4: Day Hiking | AH4: Outdoor / Hiking [MATCH] | AI4: Shell | AJ4: Jacket | AK4: 2L | AL4: Y
A5: SS27 | B5: TRUE | C5: 608192 | D5: Alert GTX Jacket Women | E5: Apparel | F5: OUT | G5: Shell | H5: Inline | I5: Women | K5: TRUE | L5: FALSE | M5: 3800 | N5: 2.1 | O5: 1809.52 | P5: 0.65159269 | Q5: Good | R5: SPECIALIST, GENERALIST MULTISPORT, INTERSPORT NORDIC, Lifestyle/DAY | S5: Gore-Tex | T5: None | W5: CO | X5: 630.45 | AA5: A | AB5: 1000 | AC5: 300 | AD5: 608192 | AE5: 4 | AF5: Outdoor | AG5: Day Hiking | AH5: Outdoor / Hiking [MATCH] | AI5: Shell | AJ5: Jacket | AK5: 2L | AL5: Y
A6: SS27 | B6: TRUE | C6: 607645 | D6: Alert Mid Pant Men | E6: Apparel | F6: OUT | G6: Legwear | H6: Inline | I6: Men | K6: TRUE | L6: FALSE | M6: 1700 | N6: 2.1 | O6: 809.52 | P6: 0.61785997 | Q6: Better | R6: SPECIALIST, GENERALIST MULTISPORT, INTERSPORT NORDIC, Lifestyle/DAY | S6: None | T6: None | W6: CO | X6: 309.35 | AA6: A | AB6: 2000 | AC6: 500 | AD6: 607645 | AE6: 4 | AF6: Outdoor | AG6: Trekking | AH6: Outdoor / Mountaineering [CHECK - activity] | AI6: Softshell | AJ6: Pant | AK6: Classic Softshell | AL6: N
A7: SS27 | B7: TRUE | C7: 607649 | D7: Alert Mid Pant Women | E7: Apparel | F7: OUT | G7: Legwear | H7: Inline | I7: Women | K7: TRUE | L7: FALSE | M7: 1700 | N7: 2.1 | O7: 809.52 | P7: 0.64852011 | Q7: Better | R7: SPECIALIST, GENERALIST MULTISPORT, INTERSPORT NORDIC, Lifestyle/DAY | S7: None | T7: None | W7: CO | X7: 284.53 | AA7: A | AB7: 2000 | AC7: 500 | AD7: 607649 | AE7: 4 | AF7: Outdoor | AG7: Trekking | AH7: Outdoor / Mountaineering [CHECK - activity] | AI7: Softshell | AJ7: Pant | AK7: Classic Softshell | AL7: N
A8: SS27 | B8: TRUE | C8: 608158 | D8: Alert Mid Shorts Men | E8: Apparel | F8: OUT | G8: Legwear | H8: Inline | I8: Men | K8: TRUE | L8: FALSE | M8: 1200 | N8: 2.1 | O8: 571.43 | Q8: Better | R8: SPECIALIST, GENERALIST MULTISPORT, INTERSPORT NORDIC | S8: None | T8: None | W8: CO | X8: 212.18 | AA8: A | AB8: 2000 | AC8: 500 | AD8: 608158 | AE8: 5 | AF8: Essentials | AG8: Trekking | AI8: Softshell | AJ8: Shorts | AK8: Classic Softshell | AL8: N
A9: SS27 | B9: TRUE | C9: 608178 | D9: Alert Mid Shorts Women | E9: Apparel | F9: OUT | G9: Legwear | H9: Inline | I9: Women | K9: TRUE | L9: FALSE | M9: 1200 | N9: 2.1 | O9: 571.43 | Q9: Better | R9: SPECIALIST, GENERALIST MULTISPORT, INTERSPORT NORDIC | S9: None | T9: None | W9: CO | X9: 198.41 | AA9: A | AB9: 2000 | AC9: 500 | AD9: 608178 | AE9: 5 | AF9: Essentials | AG9: Trekking | AI9: Softshell | AJ9: Shorts | AK9: Classic Softshell | AL9: N
A10: SS27 | B10: TRUE | C10: 608250 | D10: Apex II Hood Men | E10: Apparel | F10: OUT | G10: Softshell | H10: ABS | I10: Men | K10: TRUE | L10: FALSE | M10: 2200 | N10: 2.1 | O10: 1047.62 | Q10: Better | R10: BIG BOX, SPECIALIST, GENERALIST MULTISPORT | S10: None | T10: None | V10: XXL | W10: CO | X10: 342 | AA10: C | AB10: 800 | AC10: 500 | AD10: 608250 | AE10: 1 | AF10: Essentials | AG10: Active Essentials | AI10: Softshell | AJ10: Hooded Jacket | AK10: Classic Softshell | AL10: N
A11: SS27 | B11: TRUE | C11: 608249 | D11: Apex II Hood Women | E11: Apparel | F11: OUT | G11: Softshell | H11: ABS | I11: Women | K11: TRUE | L11: FALSE | M11: 2200 | N11: 2.1 | O11: 1047.62 | Q11: Better | R11: BIG BOX, SPECIALIST, GENERALIST MULTISPORT | S11: None | T11: None | V11: XXL | W11: CO | X11: 319.09 | AA11: C | AB11: 800 | AC11: 500 | AD11: 608249 | AE11: 1 | AF11: Essentials | AG11: Active Essentials | AI11: Softshell | AJ11: Hooded Jacket | AK11: Classic Softshell | AL11: N
A12: SS27 | B12: TRUE | C12: 607766 | D12: Aria Proof Parka Women | E12: Apparel | F12: OUT | G12: Shell | H12: Inline | I12: Women | K12: TRUE | L12: FALSE | M12: 2500 | N12: 2.1 | O12: 1190.48 | Q12: Better | R12: SPECIALIST, GENERALIST MULTISPORT, INTERSPORT NORDIC | S12: Proof | T12: None | V12: XXL | W12: CO | X12: 498.54 | AA12: B | AB12: 1000 | AC12: 300 | AD12: 607766 | AE12: 3 | AF12: Essentials | AG12: Daily Essentials | AI12: Shell | AJ12: Parka | AK12: 2L | AL12: Y
A13: SS27 | B13: TRUE | C13: 608395 | D13: Aska Proof Jacket Men | E13: Apparel | F13: OUT | G13: Shell | H13: ABS | I13: Men | K13: TRUE | L13: FALSE | M13: 2200 | N13: 2.1 | O13: 1047.62 | Q13: Good | R13: INTERSPORT NORDIC | S13: Proof | T13: None | U13: Copy of Breeze Proof Jacket 607680 | V13: Intersport | W13: CO | X13: 345.72 | AA13: A | AB13: 1000 | AC13: 300 | AD13: 608395 | AE13: 3 | AF13: Essentials | AG13: Active Essentials | AI13: Shell | AJ13: Jacket | AK13: 2L | AL13: Y
A14: SS27 | B14: TRUE | C14: 608396 | D14: Aska Proof Jacket Women | E14: Apparel | F14: OUT | G14: Shell | H14: ABS | I14: Women | K14: TRUE | L14: FALSE | M14: 2200 | N14: 2.1 | O14: 1047.62 | Q14: Good | R14: INTERSPORT NORDIC | S14: Proof | T14: None | U14: Copy of Breeze Proof Jacket 607681 | V14: Intersport | W14: CO | X14: 322.11 | AA14: A | AB14: 1000 | AC14: 300 | AD14: 608396 | AE14: 4 | AF14: Essentials | AG14: Active Essentials | AI14: Shell | AJ14: Jacket | AK14: 2L | AL14: Y
A15: SS27 | B15: TRUE | C15: 608397 | D15: Aska Proof Pant Men | E15: Apparel | F15: OUT | G15: Shell | H15: ABS | I15: Men | K15: TRUE | L15: FALSE | M15: 1700 | N15: 2.1 | O15: 809.52 | Q15: Good | R15: INTERSPORT NORDIC | S15: Proof | T15: None | V15: Intersport | W15: CO | X15: 269.65 | AA15: A | AB15: 1000 | AC15: 300 | AD15: 608397 | AE15: 1 | AF15: Essentials | AG15: Active Essentials | AI15: Shell | AJ15: Pant | AK15: 2L | AL15: Y
A16: SS27 | B16: TRUE | C16: 608398 | D16: Aska Proof Pant Women | E16: Apparel | F16: OUT | G16: Shell | H16: ABS | I16: Women | K16: TRUE | L16: FALSE | M16: 1700 | N16: 2.1 | O16: 809.52 | Q16: Good | R16: INTERSPORT NORDIC | S16: Proof | T16: None | V16: Intersport | W16: CO | X16: 263.72 | AA16: A | AB16: 1000 | AC16: 300 | AD16: 608398 | AE16: 1 | AF16: Essentials | AG16: Active Essentials | AI16: Shell | AJ16: Pant | AK16: 2L | AL16: Y
A17: SS27 | B17: TRUE | C17: 608656 | D17: Aska Softshell Hood Men | E17: Apparel | F17: OUT | G17: Softshell | H17: ABS | I17: Men | K17: FALSE | L17: FALSE | M17: 1800 | N17: 2.1 | O17: 714.29 | Q17: Good | R17: INTERSPORT NORDIC | S17: None | T17: None | U17: copy of korp softshell hood 608552 | V17: Intersport | W17: NEW | X17: 241.92 | AA17: A | AB17: 1000 | AC17: 300 | AD17: 608656 | AE17: 4 | AF17: Outdoor | AG17: Day Hiking | AH17: Outdoor / Hiking [MATCH] | AI17: Softshell | AJ17: Hooded Jacket | AK17: Classic Softshell | AL17: N | AM17: Check - Day Hike? | WB: not in this workbook — cannot verify
A18: SS27 | B18: TRUE | C18: 608658 | D18: Aska Softshell Hood Women | E18: Apparel | F18: OUT | G18: Softshell | H18: ABS | I18: Women | K18: FALSE | L18: FALSE | M18: 1800 | N18: 2.1 | O18: 714.29 | Q18: Good | R18: INTERSPORT NORDIC | S18: None | T18: None | U18: copy of korp softshell hood 608553 | V18: Intersport | W18: NEW | X18: 221.62 | AA18: A | AB18: 1000 | AC18: 300 | AD18: 608658 | AE18: 4 | AF18: Outdoor | AG18: Day Hiking | AH18: Outdoor / Hiking [MATCH] | AI18: Softshell | AJ18: Hooded Jacket | AK18: Classic Softshell | AL18: N | AM18: Check - Day Hike? | WB: not in this workbook — cannot verify
A19: SS27 | B19: TRUE | C19: 608657 | D19: Aska Softshell Pant Men | E19: Apparel | F19: OUT | G19: Softshell | H19: ABS | I19: Men | K19: FALSE | L19: FALSE | M19: 1400 | N19: 2.1 | O19: 571.43 | Q19: Good | R19: INTERSPORT NORDIC | S19: None | T19: None | U19: copy of korp softshell Pant 608554 | V19: Intersport | W19: NEW | X19: 200.22 | AA19: A | AB19: 1000 | AC19: 300 | AD19: 608657 | AE19: 1 | AF19: Outdoor | AG19: Day Hiking | AH19: Outdoor / Hiking [MATCH] | AI19: Softshell | AJ19: Pant | AK19: Classic Softshell | AL19: N | AM19: Check - Day Hike? | WB: not in this workbook — cannot verify
A20: SS27 | B20: TRUE | C20: 608659 | D20: Aska Softshell Pant Women | E20: Apparel | F20: OUT | G20: Softshell | H20: ABS | I20: Women | K20: FALSE | L20: FALSE | M20: 1400 | N20: 2.1 | O20: 571.43 | Q20: Good | R20: INTERSPORT NORDIC | S20: None | T20: None | U20: copy of korp softshell Pant 608555 | V20: Intersport | W20: NEW | X20: 193.69 | AA20: A | AB20: 1000 | AC20: 300 | AD20: 608659 | AE20: 1 | AF20: Outdoor | AG20: Day Hiking | AH20: Outdoor / Hiking [MATCH] | AI20: Softshell | AJ20: Pant | AK20: Classic Softshell | AL20: N | AM20: Check - Day Hike? | WB: not in this workbook — cannot verify
A21: SS27 | B21: TRUE | C21: 607593 | D21: Astral GTX II Jacket Men | E21: Apparel | F21: OUT | G21: Shell | H21: Inline | I21: Men | K21: TRUE | L21: FALSE | M21: 4500 | N21: 2.1 | O21: 2142.86 | Q21: Better | R21: SPECIALIST, GENERALIST MULTISPORT, INTERSPORT NORDIC | S21: Gore-Tex | T21: None | W21: CO | X21: 1032.36 | AA21: A | AB21: 1000 | AC21: 300 | AD21: 607593 | AE21: 5 | AF21: Essentials | AG21: Active Essentials | AH21: Essentials / Essentials/Everyday [MATCH] | AI21: Shell | AJ21: Jacket | AK21: 2L | AL21: Y
A22: SS27 | B22: TRUE | C22: 607563 | D22: Astral GTX II Jacket Women | E22: Apparel | F22: OUT | G22: Shell | H22: Inline | I22: Women | K22: TRUE | L22: FALSE | M22: 4500 | N22: 2.1 | O22: 2142.86 | Q22: Better | R22: SPECIALIST, GENERALIST MULTISPORT, INTERSPORT NORDIC | S22: Gore-Tex | T22: None | W22: CO | X22: 919.5 | AA22: A | AB22: 1000 | AC22: 300 | AD22: 607563 | AE22: 5 | AF22: Essentials | AG22: Active Essentials | AH22: Essentials / Essentials/Everyday [MATCH] | AI22: Shell | AJ22: Jacket | AK22: 2L | AL22: Y
A23: SS27 | B23: TRUE | C23: 608587 | D23: Brand Five Panel Cap | E23: Apparel | F23: DAY | G23: Accessories | H23: Inline | I23: Unisex | K23: TRUE | L23: FALSE | M23: 450 | N23: 2.1 | O23: 214.29 | Q23: Better | R23: SPECIALIST, GENERALIST MULTISPORT, INTERSPORT NORDIC, BIG BOX | S23: None | T23: None | W23: CO | X23: 67.26 | AA23: B | AB23: 600 | AC23: 600 | AD23: 608587 | AE23: 6 | AF23: Essentials | AG23: Active Essentials | AI23: Accessories | AJ23: Headwear | AK23: Cap | AL23: N
A24: SS27 | B24: TRUE | C24: 607680 | D24: Breeze Proof Jacket Men | E24: Apparel | F24: OUT | G24: Shell | H24: Inline | I24: Men | K24: TRUE | L24: FALSE | M24: 2000 | N24: 2.1 | O24: 952.38 | Q24: Good | R24: SPECIALIST, GENERALIST MULTISPORT, INTERSPORT NORDIC, Lifestyle/DAY | S24: Proof | T24: None | W24: CO | X24: 334.57 | AA24: A | AB24: 1000 | AC24: 300 | AD24: 607680 | AE24: 7 | AF24: Essentials | AG24: Daily Essentials | AH24: Outdoor / Hiking [CHECK - collection + activity] | AI24: Shell | AJ24: Jacket | AK24: 2L | AL24: Y
A25: SS27 | B25: TRUE | C25: 607681 | D25: Breeze Proof Jacket Women | E25: Apparel | F25: OUT | G25: Shell | H25: Inline | I25: Women | K25: TRUE | L25: FALSE | M25: 2000 | N25: 2.1 | O25: 952.38 | Q25: Good | R25: SPECIALIST, GENERALIST MULTISPORT, INTERSPORT NORDIC, Lifestyle/DAY | S25: Proof | T25: None | W25: CO | X25: 314.78 | AA25: A | AB25: 1000 | AC25: 300 | AD25: 607681 | AE25: 6 | AF25: Essentials | AG25: Daily Essentials | AH25: Outdoor / Hiking [CHECK - collection + activity] | AI25: Shell | AJ25: Jacket | AK25: 2L | AL25: Y
A26: SS27 | B26: TRUE | C26: 608351 | D26: Buteo Mid II Jacket Men | E26: Apparel | F26: OUT | G26: Midlayer | H26: Inline | I26: Men | K26: TRUE | L26: FALSE | M26: 900 | N26: 2.1 | O26: 428.57 | Q26: Good | R26: SPECIALIST, GENERALIST MULTISPORT, INTERSPORT NORDIC, Lifestyle/DAY | S26: Polartec | T26: None | W26: CO | X26: 145.36 | Y26: 605073 | Z26: Buteo Mid Jacket Men | AA26: A | AB26: 1000 | AC26: 300 | AD26: 608351 | AE26: 6 | AF26: Essentials | AG26: Active Essentials | AH26: Essentials / Essentials/Everyday [MATCH] | AI26: Fleece/Midlayer | AJ26: Jacket | AK26: Midweight | AL26: N
A27: SS27 | B27: TRUE | C27: 608352 | D27: Buteo Mid II Jacket Women | E27: Apparel | F27: OUT | G27: Midlayer | H27: Inline | I27: Women | K27: TRUE | L27: FALSE | M27: 900 | N27: 2.1 | O27: 428.57 | Q27: Good | R27: SPECIALIST, GENERALIST MULTISPORT, INTERSPORT NORDIC, Lifestyle/DAY | S27: Polartec | T27: None | W27: CO | X27: 137.49 | Y27: 605074 | Z27: Buteo Mid Jacket Women | AA27: A | AB27: 1000 | AC27: 300 | AD27: 608352 | AE27: 6 | AF27: Essentials | AG27: Active Essentials | AH27: Essentials / Essentials/Everyday [MATCH] | AI27: Fleece/Midlayer | AJ27: Jacket | AK27: Midweight | AL27: N
A28: SS27 | B28: TRUE | C28: 608421 | D28: Chaos GTX II Jacket Men | E28: Apparel | F28: OUT | G28: Shell | H28: ABS | I28: Men | K28: TRUE | L28: FALSE | M28: 3500 | N28: 2.1 | O28: 1666.67 | Q28: Good | R28: INTERSPORT NORDIC | S28: Gore-Tex | T28: None | V28: Intersport | W28: CO | X28: 545.72 | AA28: B | AB28: 1000 | AC28: 300 | AD28: 608421 | AE28: 3 | AF28: Essentials | AG28: Active Essentials | AH28: Essentials / Essentials/Everyday [MATCH] | AI28: Shell | AJ28: Jacket | AK28: 2L | AL28: Y
A29: SS27 | B29: TRUE | C29: 608422 | D29: Chaos GTX II Jacket Women | E29: Apparel | F29: OUT | G29: Shell | H29: ABS | I29: Women | K29: TRUE | L29: FALSE | M29: 3500 | N29: 2.1 | O29: 1666.67 | Q29: Good | R29: INTERSPORT NORDIC | S29: Gore-Tex | T29: None | V29: Intersport | W29: CO | X29: 515.04 | AA29: B | AB29: 1000 | AC29: 300 | AD29: 608422 | AE29: 3 | AF29: Outdoor | AG29: Active Essentials | AH29: Essentials / Essentials/Everyday [CHECK - collection] | AI29: Shell | AJ29: Jacket | AK29: 2L | AL29: Y
A30: SS27 | B30: TRUE | C30: 607646 | D30: Front Flex Pant Men | E30: Apparel | F30: OUT | G30: Legwear | H30: Inline | I30: Men | K30: TRUE | L30: FALSE | M30: 1500 | N30: 2.1 | O30: 714.29 | Q30: Better | R30: SPECIALIST, GENERALIST MULTISPORT, INTERSPORT NORDIC | S30: None | T30: None | W30: CO | X30: 290.96 | AA30: B | AB30: 2000 | AC30: 500 | AD30: 607646 | AE30: 1 | AF30: Outdoor | AG30: Trekking | AH30: Outdoor / Mountaineering [CHECK - activity] | AI30: Softshell | AJ30: Pant | AK30: Classic Softshell | AL30: N
A31: SS27 | B31: TRUE | C31: 607650 | D31: Front Flex Pant Women | E31: Apparel | F31: OUT | G31: Legwear | H31: Inline | I31: Women | K31: TRUE | L31: FALSE | M31: 1500 | N31: 2.1 | O31: 714.29 | Q31: Better | R31: SPECIALIST, GENERALIST MULTISPORT, INTERSPORT NORDIC | S31: None | T31: None | W31: CO | X31: 274.38 | AA31: B | AB31: 2000 | AC31: 500 | AD31: 607650 | AE31: 1 | AF31: Outdoor | AG31: Trekking | AH31: Outdoor / Mountaineering [CHECK - activity] | AI31: Softshell | AJ31: Pant | AK31: Classic Softshell | AL31: N
A32: SS27 | B32: TRUE | C32: 607823 | D32: Front Proof II Jacket Men | E32: Apparel | F32: OUT | G32: Shell | H32: Inline | I32: Men | K32: TRUE | L32: FALSE | M32: 3300 | N32: 2.1 | O32: 1571.43 | Q32: Better | R32: SPECIALIST, GENERALIST MULTISPORT, INTERSPORT NORDIC, Lifestyle/DAY | S32: Proof | T32: None | W32: CO | X32: 671.22 | AA32: A | AB32: 1000 | AC32: 300 | AD32: 607823 | AE32: 5 | AF32: Outdoor | AG32: Trekking | AH32: Outdoor / Trekking [MATCH] | AI32: Shell | AJ32: Jacket | AK32: 3L | AL32: Y
A33: SS27 | B33: TRUE | C33: 607821 | D33: Front Proof II Jacket Women | E33: Apparel | F33: OUT | G33: Shell | H33: Inline | I33: Women | K33: TRUE | L33: FALSE | M33: 3300 | N33: 2.1 | O33: 1571.43 | Q33: Better | R33: SPECIALIST, GENERALIST MULTISPORT, INTERSPORT NORDIC, Lifestyle/DAY | S33: Proof | T33: None | W33: CO | X33: 637.9 | AA33: A | AB33: 1000 | AC33: 300 | AD33: 607821 | AE33: 5 | AF33: Outdoor | AG33: Trekking | AH33: Outdoor / Trekking [MATCH] | AI33: Shell | AJ33: Jacket | AK33: 3L | AL33: Y
A34: SS27 | B34: TRUE | C34: 608652 | D34: Gabbro II Pant Men | E34: Apparel | F34: OUT | G34: Softshell | H34: ABS | I34: Men | K34: TRUE | L34: FALSE | M34: 2200 | N34: 2.1 | O34: 1047.62 | Q34: Better | R34: BIG BOX, SPECIALIST, GENERALIST MULTISPORT | S34: None | T34: None | V34: XXL | W34: CO | X34: 323.46 | Y34: 608247 | Z34: Gabbro Pant Men | AA34: C | AB34: 1000 | AC34: 300 | AD34: 608652 | AE34: 1 | AF34: Essentials | AG34: Active Essentials | AI34: Softshell | AJ34: Pant | AK34: Classic Softshell | AL34: N
A35: SS27 | B35: TRUE | C35: 608653 | D35: Gabbro II Pant Women | E35: Apparel | F35: OUT | G35: Softshell | H35: ABS | I35: Women | K35: TRUE | L35: FALSE | M35: 2200 | N35: 2.1 | O35: 1047.62 | Q35: Better | R35: BIG BOX, SPECIALIST, GENERALIST MULTISPORT | S35: None | T35: None | V35: XXL | W35: CO | X35: 301.45 | Y35: 608248 | Z35: Gabbro Pant Women | AA35: C | AB35: 1000 | AC35: 300 | AD35: 608653 | AE35: 1 | AF35: Essentials | AG35: Active Essentials | AI35: Softshell | AJ35: Pant | AK35: Classic Softshell | AL35: N
A36: SS27 | B36: TRUE | C36: 608204 | D36: Haglöfs Bandana | E36: Apparel | F36: DAY | G36: Accessories | H36: Inline | I36: Unisex | K36: TRUE | L36: FALSE | M36: 400 | N36: 2.1 | O36: 190.48 | Q36: Better | R36: SPECIALIST, GENERALIST MULTISPORT, INTERSPORT NORDIC | S36: None | T36: None | W36: CO | X36: 76.85 | AA36: B | AB36: 500 | AC36: 500 | AD36: 608204 | AE36: 4 | AF36: Essentials | AG36: Daily Essentials | AI36: Accessories | AJ36: Headwear | AK36: Bandana | AL36: N
A37: SS27 | B37: TRUE | C37: 607656 | D37: Haglöfs Cap | E37: Apparel | F37: DAY | G37: Accessories | H37: Inline | I37: Unisex | K37: TRUE | L37: FALSE | M37: 400 | N37: 2.1 | O37: 190.48 | Q37: Good | R37: SPECIALIST, GENERALIST MULTISPORT, INTERSPORT NORDIC, BIG BOX | S37: None | T37: None | W37: CO | X37: 68.88 | AA37: A | AB37: 600 | AC37: 600 | AD37: 607656 | AE37: 5 | AF37: Essentials | AG37: Daily Essentials | AI37: Accessories | AJ37: Headwear | AK37: Cap | AL37: N
A38: SS27 | B38: TRUE | C38: 608164 | D38: Haglöfs Hoodie Men | E38: Apparel | F38: DAY | G38: Midlayer | H38: Inline | I38: Men | K38: TRUE | L38: FALSE | M38: 1500 | N38: 2.1 | O38: 714.29 | Q38: Better | R38: SPECIALIST, GENERALIST MULTISPORT, INTERSPORT NORDIC | S38: None | T38: None | W38: CO | X38: 318.03 | AA38: B | AB38: 500 | AC38: 500 | AD38: 608164 | AE38: 3 | AF38: Essentials | AG38: Daily Essentials | AH38: Essentials / Essentials/Everyday [MATCH] | AI38: Fleece/Midlayer | AJ38: Hooded Jacket | AK38: Midweight | AL38: N
A39: SS27 | B39: TRUE | C39: 608184 | D39: Haglöfs Hoodie Women | E39: Apparel | F39: DAY | G39: Midlayer | H39: Inline | I39: Women | K39: TRUE | L39: FALSE | M39: 1500 | N39: 2.1 | O39: 714.29 | Q39: Better | R39: SPECIALIST, GENERALIST MULTISPORT, INTERSPORT NORDIC | S39: None | T39: None | W39: CO | X39: 285.58 | AA39: B | AB39: 500 | AC39: 500 | AD39: 608184 | AE39: 3 | AF39: Essentials | AG39: Daily Essentials | AH39: Essentials / Essentials/Everyday [MATCH] | AI39: Fleece/Midlayer | AJ39: Hooded Jacket | AK39: Midweight | AL39: N
A40: SS27 | B40: TRUE | C40: 607660 | D40: Haglöfs LS Tee Men | E40: Apparel | F40: DAY | G40: Tops | H40: Inline | I40: Men | K40: TRUE | L40: FALSE | M40: 800 | N40: 2.1 | O40: 380.95 | Q40: Better | R40: SPECIALIST, GENERALIST MULTISPORT, INTERSPORT NORDIC, BIG BOX, Lifestyle/DAY | S40: None | T40: None | W40: CO | X40: 159.59 | AA40: B | AB40: 500 | AC40: 500 | AD40: 607660 | AE40: 5 | AF40: Essentials | AG40: Daily Essentials | AH40: Essentials / Essentials/Everyday [MATCH] | AI40: Tops | AJ40: Long Sleeve | AK40: Cotton/Graphic Tee | AL40: N
...

Sheet FW27
B1: =COLUMN()-1 -> 1 | C1: =COLUMN()-1 -> 2 | D1: =COLUMN()-1 -> 3 | G1: =COLUMN()-1 -> 6 | I1: =COLUMN()-1 -> 8 | J1: =COLUMN()-1 -> 9 | K1: =COLUMN()-1 -> 10 | L1: =COLUMN()-1 -> 11 | M1: =COLUMN()-1 -> 12 | N1: =COLUMN()-1 -> 13 | O1: =COLUMN()-1 -> 14 | P1: =COLUMN()-1 -> 15 | ... AE1: =COLUMN()-1 -> 30 | AK1: Product Life Cycle: Launch Season, Update Season, Last Season Offered (TOBIAS) | AM1: ORIGINAL | AN1: ORIGINAL | AO1: CENTRIC | AP1: CENTRIC | AQ1: CENTRIC | BA1: Product Life Cycle: Launch Season, Update Season, Last Season Offered
A2: Active | B2: Code | C2: Style | D2: Business Area | G2: Product Concept | I2: Category/Layer | J2: Collection Type | K2: Gender | L2: Proposed Drop Week | M2: Carry Over | N2: Update | O2: Target RRP | P2: Mark-up | Q2: WP | R2: GM0% | S2: Product Hierarchy | T2: Distribution Segmentation | U2: Main technology platform | V2: Secondary technology platform | W2: Style Comment | X2: ABS Customer | Y2: STATUS | Z2: LANDED COST SEK | AA2: REF_CODE | AB2: REF_NAME | AC2: Classification ABC | AD2: MOQ Style | AE2: MOQ Color | AF2: Check Pricing | AG2: Color Options | AH2: AF EXIST | AI2: LSO / Exit Season | AJ2: Product Life Cycle: Launch Season, Update Season, Last Season Offered | AK2: LS | AL2: US | AM2: Collection | AN2: NEW MAPPING: Activity | AO2: Collection | AP2: Activity | AQ2: Concept | AR2: COMMENT | AS2: Category/Layer(V2) | AT2: Silhouette | AU2: Category/Layer Subtype | AV2: Waterproof | AW2: Attribution Review | AX2: Franchise/Family | AY2: Note | BA2: LS | BB2: US | BC2: LSO
A3: TRUE | B3: 608656 | C3: Aska Softshell Hood Men | D3: Apparel | G3: OUT | I3: Softshell | J3: ABS | K3: Men | M3: TRUE | N3: FALSE | O3: 1800 | P3: 2.1 | Q3: 857.14 | R3: 0.72276408 | S3: Good | U3: None | V3: None | X3: Intersport | Y3: =IF(M3=TRUE,"CO",IF(N3=TRUE,"UPDATE","NEW")) -> CO | Z3: =_xlfn.XLOOKUP($B3,[1]F27!$C:$C,[1]F27!$BV:$BV) -> #ERROR! | AD3: =_xlfn.XLOOKUP($B3,[1]F27!$C:$C,[1]F27!$Y:$Y) -> #ERROR! | AE3: =_xlfn.XLOOKUP($B3,[1]F27!$C:$C,[1]F27!$Z:$Z) -> #ERROR! | AF3: =_xlfn.XLOOKUP($B3,[2]PRICING!$B:$B,[2]PRICING!$B:$B,"MISSING") -> #ERROR! | AG3: =COUNTIFS([2]ACTIVE_SCO!$B:$B,$B3,[2]ACTIVE_SCO!$P:$P,"Y") -> #ERROR! | AI3: FW28+ | AJ3: PLC: LS?? US-?? LSO-?? | AK3: SS27 | AM3: Outdoor | AN3: Day Hiking | AO3: Outdoor | AP3: Hiking | AS3: Softshell | AT3: Hooded Jacket | AU3: Classic Softshell | AV3: N | BA3: SS27
A4: TRUE | B4: 608658 | C4: Aska Softshell Hood Women | D4: Apparel | G4: OUT | I4: Softshell | J4: ABS | K4: Women | M4: TRUE | N4: FALSE | O4: 1800 | P4: 2.1 | Q4: 857.14 | R4: 0.74220081 | S4: Good | U4: None | V4: None | X4: Intersport | Y4: =IF(M4=TRUE,"CO",IF(N4=TRUE,"UPDATE","NEW")) -> CO | Z4: =_xlfn.XLOOKUP($B4,[1]F27!$C:$C,[1]F27!$BV:$BV) -> #ERROR! | AD4: =_xlfn.XLOOKUP($B4,[1]F27!$C:$C,[1]F27!$Y:$Y) -> #ERROR! | AE4: =_xlfn.XLOOKUP($B4,[1]F27!$C:$C,[1]F27!$Z:$Z) -> #ERROR! | AF4: =_xlfn.XLOOKUP($B4,[2]PRICING!$B:$B,[2]PRICING!$B:$B,"MISSING") -> #ERROR! | AG4: =COUNTIFS([2]ACTIVE_SCO!$B:$B,$B4,[2]ACTIVE_SCO!$P:$P,"Y") -> #ERROR! | AI4: FW28+ | AJ4: PLC: LS?? US-?? LSO-?? | AK4: SS27 | AM4: Outdoor | AN4: Day Hiking | AO4: Outdoor | AP4: Hiking | AS4: Softshell | AT4: Hooded Jacket | AU4: Classic Softshell | AV4: N | BA4: SS27
A5: TRUE | B5: 608363 | C5: Aska Insulated Jacket Men | D5: Apparel | G5: OUT | I5: Shell | J5: ABS | K5: Men | M5: TRUE | N5: FALSE | O5: 2500 | P5: 2.1 | Q5: 1190.48 | R5: 0.6562395 | S5: Good | U5: Proof | V5: Mimic | X5: Intersport | Y5: =IF(M5=TRUE,"CO",IF(N5=TRUE,"UPDATE","NEW")) -> CO | Z5: =_xlfn.XLOOKUP($B5,[1]F27!$C:$C,[1]F27!$BV:$BV) -> #ERROR! | AD5: =_xlfn.XLOOKUP($B5,[1]F27!$C:$C,[1]F27!$Y:$Y) -> #ERROR! | AE5: =_xlfn.XLOOKUP($B5,[1]F27!$C:$C,[1]F27!$Z:$Z) -> #ERROR! | AF5: =_xlfn.XLOOKUP($B5,[2]PRICING!$B:$B,[2]PRICING!$B:$B,"MISSING") -> #ERROR! | AG5: =COUNTIFS([2]ACTIVE_SCO!$B:$B,$B5,[2]ACTIVE_SCO!$P:$P,"Y") -> #ERROR! | AI5: FW28+ | AJ5: PLC: LS?? US-?? LSO-?? | AK5: FW26 | AM5: Essentials | AN5: Active Essentials | AO5: Essentials | AS5: Shell | AT5: Jacket | AU5: Insulated | AV5: Y | BA5: FW26
A6: TRUE | B6: 608365 | C6: Aska Insulated Jacket Women | D6: Apparel | G6: OUT | I6: Shell | J6: ABS | K6: Women | M6: TRUE | N6: FALSE | O6: 2500 | P6: 2.1 | Q6: 1190.48 | R6: 0.68080942 | S6: Good | U6: Proof | V6: Mimic | X6: Intersport | Y6: =IF(M6=TRUE,"CO",IF(N6=TRUE,"UPDATE","NEW")) -> CO | Z6: =_xlfn.XLOOKUP($B6,[1]F27!$C:$C,[1]F27!$BV:$BV) -> #ERROR! | AD6: =_xlfn.XLOOKUP($B6,[1]F27!$C:$C,[1]F27!$Y:$Y) -> #ERROR! | AE6: =_xlfn.XLOOKUP($B6,[1]F27!$C:$C,[1]F27!$Z:$Z) -> #ERROR! | AF6: =_xlfn.XLOOKUP($B6,[2]PRICING!$B:$B,[2]PRICING!$B:$B,"MISSING") -> #ERROR! | AG6: =COUNTIFS([2]ACTIVE_SCO!$B:$B,$B6,[2]ACTIVE_SCO!$P:$P,"Y") -> #ERROR! | AI6: FW28+ | AJ6: PLC: LS?? US-?? LSO-?? | AK6: FW26 | AM6: Essentials | AN6: Active Essentials | AO6: Essentials | AS6: Shell | AT6: Jacket | AU6: Insulated | AV6: Y | BA6: FW26
A7: TRUE | B7: 608530 | C7: Aska Insulated Pant Men | D7: Apparel | G7: OUT | I7: Shell | J7: ABS | K7: Men | M7: TRUE | N7: FALSE | O7: 2000 | P7: 2.1 | Q7: 952.38 | R7: 0.7045822 | S7: Good | U7: Proof | V7: Mimic | X7: Intersport | Y7: =IF(M7=TRUE,"CO",IF(N7=TRUE,"UPDATE","NEW")) -> CO | Z7: =_xlfn.XLOOKUP($B7,[1]F27!$C:$C,[1]F27!$BV:$BV) -> #ERROR! | AD7: =_xlfn.XLOOKUP($B7,[1]F27!$C:$C,[1]F27!$Y:$Y) -> #ERROR! | AE7: =_xlfn.XLOOKUP($B7,[1]F27!$C:$C,[1]F27!$Z:$Z) -> #ERROR! | AF7: =_xlfn.XLOOKUP($B7,[2]PRICING!$B:$B,[2]PRICING!$B:$B,"MISSING") -> #ERROR! | AG7: =COUNTIFS([2]ACTIVE_SCO!$B:$B,$B7,[2]ACTIVE_SCO!$P:$P,"Y") -> #ERROR! | AI7: FW28+ | AJ7: PLC: LS?? US-?? LSO-?? | AK7: FW26 | AM7: Essentials | AN7: Active Essentials | AO7: Essentials | AS7: Shell | AT7: Pant | AU7: Insulated | AV7: Y | BA7: FW26
A8: TRUE | B8: 608529 | C8: Aska Insulated Pant Women | D8: Apparel | G8: OUT | I8: Shell | J8: ABS | K8: Women | M8: TRUE | N8: FALSE | O8: 2000 | P8: 2.1 | Q8: 952.38 | R8: 0.71275121 | S8: Good | U8: Proof | V8: Mimic | X8: Intersport | Y8: =IF(M8=TRUE,"CO",IF(N8=TRUE,"UPDATE","NEW")) -> CO | Z8: =_xlfn.XLOOKUP($B8,[1]F27!$C:$C,[1]F27!$BV:$BV) -> #ERROR! | AD8: =_xlfn.XLOOKUP($B8,[1]F27!$C:$C,[1]F27!$Y:$Y) -> #ERROR! | AE8: =_xlfn.XLOOKUP($B8,[1]F27!$C:$C,[1]F27!$Z:$Z) -> #ERROR! | AF8: =_xlfn.XLOOKUP($B8,[2]PRICING!$B:$B,[2]PRICING!$B:$B,"MISSING") -> #ERROR! | AG8: =COUNTIFS([2]ACTIVE_SCO!$B:$B,$B8,[2]ACTIVE_SCO!$P:$P,"Y") -> #ERROR! | AI8: FW28+ | AJ8: PLC: LS?? US-?? LSO-?? | AK8: FW26 | AM8: Essentials | AN8: Active Essentials | AO8: Essentials | AS8: Shell | AT8: Pant | AU8: Insulated | AV8: Y | BA8: FW26
A9: TRUE | B9: 608395 | C9: Aska Proof Jacket Men | D9: Apparel | G9: OUT | I9: Shell | J9: ABS | K9: Men | M9: TRUE | N9: FALSE | O9: 2200 | P9: 2.1 | Q9: 1047.62 | R9: 0.67609439 | S9: Good | U9: Proof | V9: None | X9: Intersport | Y9: =IF(M9=TRUE,"CO",IF(N9=TRUE,"UPDATE","NEW")) -> CO | Z9: =_xlfn.XLOOKUP($B9,[1]F27!$C:$C,[1]F27!$BV:$BV) -> #ERROR! | AD9: =_xlfn.XLOOKUP($B9,[1]F27!$C:$C,[1]F27!$Y:$Y) -> #ERROR! | AE9: =_xlfn.XLOOKUP($B9,[1]F27!$C:$C,[1]F27!$Z:$Z) -> #ERROR! | AF9: =_xlfn.XLOOKUP($B9,[2]PRICING!$B:$B,[2]PRICING!$B:$B,"MISSING") -> #ERROR! | AG9: =COUNTIFS([2]ACTIVE_SCO!$B:$B,$B9,[2]ACTIVE_SCO!$P:$P,"Y") -> #ERROR! | AI9: FW28+ | AJ9: PLC: LS?? US-?? LSO-?? | AK9: SS26 | AM9: Essentials | AN9: Active Essentials | AO9: Essentials | AS9: Shell | AT9: Jacket | AU9: 2L | AV9: Y | BA9: SS26
A10: TRUE | B10: 608396 | C10: Aska Proof Jacket Women | D10: Apparel | G10: OUT | I10: Shell | J10: ABS | K10: Women | M10: TRUE | N10: FALSE | O10: 2200 | P10: 2.1 | Q10: 1047.62 | R10: 0.698173 | S10: Good | U10: Proof | V10: None | X10: Intersport | Y10: =IF(M10=TRUE,"CO",IF(N10=TRUE,"UPDATE","NEW")) -> CO | Z10: =_xlfn.XLOOKUP($B10,[1]F27!$C:$C,[1]F27!$BV:$BV) -> #ERROR! | AD10: =_xlfn.XLOOKUP($B10,[1]F27!$C:$C,[1]F27!$Y:$Y) -> #ERROR! | AE10: =_xlfn.XLOOKUP($B10,[1]F27!$C:$C,[1]F27!$Z:$Z) -> #ERROR! | AF10: =_xlfn.XLOOKUP($B10,[2]PRICING!$B:$B,[2]PRICING!$B:$B,"MISSING") -> #ERROR! | AG10: =COUNTIFS([2]ACTIVE_SCO!$B:$B,$B10,[2]ACTIVE_SCO!$P:$P,"Y") -> #ERROR! | AI10: FW28+ | AJ10: PLC: LS?? US-?? LSO-?? | AK10: SS26 | AM10: Essentials | AN10: Active Essentials | AO10: Essentials | AS10: Shell | AT10: Jacket | AU10: 2L | AV10: Y | BA10: SS26
A11: TRUE | B11: 608397 | C11: Aska Proof Pant Men | D11: Apparel | G11: OUT | I11: Shell | J11: ABS | K11: Men | M11: TRUE | N11: FALSE | O11: 1700 | P11: 2.1 | Q11: 809.52 | R11: 0.67289258 | S11: Good | U11: Proof | V11: None | X11: Intersport | Y11: =IF(M11=TRUE,"CO",IF(N11=TRUE,"UPDATE","NEW")) -> CO | Z11: =_xlfn.XLOOKUP($B11,[1]F27!$C:$C,[1]F27!$BV:$BV) -> #ERROR! | AD11: =_xlfn.XLOOKUP($B11,[1]F27!$C:$C,[1]F27!$Y:$Y) -> #ERROR! | AE11: =_xlfn.XLOOKUP($B11,[1]F27!$C:$C,[1]F27!$Z:$Z) -> #ERROR! | AF11: =_xlfn.XLOOKUP($B11,[2]PRICING!$B:$B,[2]PRICING!$B:$B,"MISSING") -> #ERROR! | AG11: =COUNTIFS([2]ACTIVE_SCO!$B:$B,$B11,[2]ACTIVE_SCO!$P:$P,"Y") -> #ERROR! | AI11: FW28+ | AJ11: PLC: LS?? US-?? LSO-?? | AK11: SS26 | AM11: Essentials | AN11: Active Essentials | AO11: Essentials | AS11: Shell | AT11: Pant | AU11: 2L | AV11: Y | BA11: SS26
A12: TRUE | B12: 608398 | C12: Aska Proof Pant Women | D12: Apparel | G12: OUT | I12: Shell | J12: ABS | K12: Women | M12: TRUE | N12: FALSE | O12: 1700 | P12: 2.1 | Q12: 809.52 | R12: 0.68005732 | S12: Good | U12: Proof | V12: None | X12: Intersport | Y12: =IF(M12=TRUE,"CO",IF(N12=TRUE,"UPDATE","NEW")) -> CO | Z12: =_xlfn.XLOOKUP($B12,[1]F27!$C:$C,[1]F27!$BV:$BV) -> #ERROR! | AD12: =_xlfn.XLOOKUP($B12,[1]F27!$C:$C,[1]F27!$Y:$Y) -> #ERROR! | AE12: =_xlfn.XLOOKUP($B12,[1]F27!$C:$C,[1]F27!$Z:$Z) -> #ERROR! | AF12: =_xlfn.XLOOKUP($B12,[2]PRICING!$B:$B,[2]PRICING!$B:$B,"MISSING") -> #ERROR! | AG12: =COUNTIFS([2]ACTIVE_SCO!$B:$B,$B12,[2]ACTIVE_SCO!$P:$P,"Y") -> #ERROR! | AI12: FW28+ | AJ12: PLC: LS?? US-?? LSO-?? | AK12: SS26 | AM12: Essentials | AN12: Active Essentials | AO12: Essentials | AS12: Shell | AT12: Pant | AU12: 2L | AV12: Y | BA12: SS26
A13: FALSE | B13: 608250 | C13: Apex II Hood Men | D13: Apparel | G13: OUT | I13: Softshell | J13: Inline | K13: Men | M13: TRUE | N13: FALSE | O13: 2200 | P13: 2.1 | Q13: 1047.62 | R13: 0.67951165 | S13: Better | U13: None | V13: None | X13: XXL | Y13: =IF(M13=TRUE,"CO",IF(N13=TRUE,"UPDATE","NEW")) -> CO | Z13: =_xlfn.XLOOKUP($B13,[1]F27!$C:$C,[1]F27!$BV:$BV) -> #ERROR! | AD13: =_xlfn.XLOOKUP($B13,[1]F27!$C:$C,[1]F27!$Y:$Y) -> #ERROR! | AE13: =_xlfn.XLOOKUP($B13,[1]F27!$C:$C,[1]F27!$Z:$Z) -> #ERROR! | AF13: =_xlfn.XLOOKUP($B13,[2]PRICING!$B:$B,[2]PRICING!$B:$B,"MISSING") -> #ERROR! | AG13: =COUNTIFS([2]ACTIVE_SCO!$B:$B,$B13,[2]ACTIVE_SCO!$P:$P,"Y") -> #ERROR! | AI13: REVIEW
A14: FALSE | B14: 608249 | C14: Apex II Hood Women | D14: Apparel | G14: OUT | I14: Softshell | J14: Inline | K14: Women | M14: TRUE | N14: FALSE | O14: 2200 | P14: 2.1 | Q14: 1047.62 | R14: 0.70093164 | S14: Better | U14: None | V14: None | X14: XXL | Y14: =IF(M14=TRUE,"CO",IF(N14=TRUE,"UPDATE","NEW")) -> CO | Z14: =_xlfn.XLOOKUP($B14,[1]F27!$C:$C,[1]F27!$BV:$BV) -> #ERROR! | AD14: =_xlfn.XLOOKUP($B14,[1]F27!$C:$C,[1]F27!$Y:$Y) -> #ERROR! | AE14: =_xlfn.XLOOKUP($B14,[1]F27!$C:$C,[1]F27!$Z:$Z) -> #ERROR! | AF14: =_xlfn.XLOOKUP($B14,[2]PRICING!$B:$B,[2]PRICING!$B:$B,"MISSING") -> #ERROR! | AG14: =COUNTIFS([2]ACTIVE_SCO!$B:$B,$B14,[2]ACTIVE_SCO!$P:$P,"Y") -> #ERROR! | AI14: REVIEW
A15: TRUE | B15: 608451 | C15: Base Mimic II Hood Men | D15: Apparel | G15: OUT | I15: Insulation | J15: ABS | K15: Men | M15: TRUE | N15: FALSE | O15: 2200 | P15: 2.1 | Q15: 1047.62 | R15: 0.72570207 | S15: Good | U15: Mimic | V15: None | X15: XXL | Y15: =IF(M15=TRUE,"CO",IF(N15=TRUE,"UPDATE","NEW")) -> CO | Z15: =_xlfn.XLOOKUP($B15,[1]F27!$C:$C,[1]F27!$BV:$BV) -> #ERROR! | AD15: =_xlfn.XLOOKUP($B15,[1]F27!$C:$C,[1]F27!$Y:$Y) -> #ERROR! | AE15: =_xlfn.XLOOKUP($B15,[1]F27!$C:$C,[1]F27!$Z:$Z) -> #ERROR! | AF15: =_xlfn.XLOOKUP($B15,[2]PRICING!$B:$B,[2]PRICING!$B:$B,"MISSING") -> #ERROR! | AG15: =COUNTIFS([2]ACTIVE_SCO!$B:$B,$B15,[2]ACTIVE_SCO!$P:$P,"Y") -> #ERROR! | AI15: FW28+ | AJ15: PLC: LS?? US-?? LSO-?? | AK15: Pre S23 | AL15: FW25 | AM15: Essentials | AN15: Active Essentials | AO15: Essentials | AS15: Insulation | AT15: Hooded Jacket | AU15: Midweight Synthetic | AV15: N | BA15: Pre S23 | BB15: FW25
A16: TRUE | B16: 608452 | C16: Base Mimic II Hood Women | D16: Apparel | G16: OUT | I16: Insulation | J16: ABS | K16: Women | M16: TRUE | N16: FALSE | O16: 2200 | P16: 2.1 | Q16: 1047.62 | R16: 0.73729024 | S16: Good | U16: Mimic | V16: None | X16: XXL | Y16: =IF(M16=TRUE,"CO",IF(N16=TRUE,"UPDATE","NEW")) -> CO | Z16: =_xlfn.XLOOKUP($B16,[1]F27!$C:$C,[1]F27!$BV:$BV) -> #ERROR! | AD16: =_xlfn.XLOOKUP($B16,[1]F27!$C:$C,[1]F27!$Y:$Y) -> #ERROR! | AE16: =_xlfn.XLOOKUP($B16,[1]F27!$C:$C,[1]F27!$Z:$Z) -> #ERROR! | AF16: =_xlfn.XLOOKUP($B16,[2]PRICING!$B:$B,[2]PRICING!$B:$B,"MISSING") -> #ERROR! | AG16: =COUNTIFS([2]ACTIVE_SCO!$B:$B,$B16,[2]ACTIVE_SCO!$P:$P,"Y") -> #ERROR! | AI16: FW28+ | AJ16: PLC: LS?? US-?? LSO-?? | AK16: Pre S23 | AL16: FW25 | AM16: Essentials | AN16: Active Essentials | AO16: Essentials | AS16: Insulation | AT16: Hooded Jacket | AU16: Midweight Synthetic | AV16: N | BA16: Pre S23 | BB16: FW25
A17: TRUE | B17: 608454 | C17: Base Mimic II Jacket Men | D17: Apparel | G17: OUT | I17: Insulation | J17: ABS | K17: Men | M17: TRUE | N17: FALSE | O17: 2000 | P17: 2.1 | Q17: 952.38 | R17: 0.72113022 | S17: Good | U17: Mimic | V17: None | X17: XXL | Y17: =IF(M17=TRUE,"CO",IF(N17=TRUE,"UPDATE","NEW")) -> CO | Z17: =_xlfn.XLOOKUP($B17,[1]F27!$C:$C,[1]F27!$BV:$BV) -> #ERROR! | AD17: =_xlfn.XLOOKUP($B17,[1]F27!$C:$C,[1]F27!$Y:$Y) -> #ERROR! | AE17: =_xlfn.XLOOKUP($B17,[1]F27!$C:$C,[1]F27!$Z:$Z) -> #ERROR! | AF17: =_xlfn.XLOOKUP($B17,[2]PRICING!$B:$B,[2]PRICING!$B:$B,"MISSING") -> #ERROR! | AG17: =COUNTIFS([2]ACTIVE_SCO!$B:$B,$B17,[2]ACTIVE_SCO!$P:$P,"Y") -> #ERROR! | AI17: FW28+ | AJ17: PLC: LS?? US-?? LSO-?? | AK17: Pre S23 | AL17: FW25 | AM17: Essentials | AN17: Active Essentials | AO17: Essentials | AS17: Insulation | AT17: Jacket | AU17: Midweight Synthetic | AV17: N | BA17: Pre S23 | BB17: FW25
A18: TRUE | B18: 608453 | C18: Base Mimic II Jacket Women | D18: Apparel | G18: OUT | I18: Insulation | J18: ABS | K18: Women | M18: TRUE | N18: FALSE | O18: 2000 | P18: 2.1 | Q18: 952.38 | R18: 0.72759823 | S18: Good | U18: Mimic | V18: None | X18: XXL | Y18: =IF(M18=TRUE,"CO",IF(N18=TRUE,"UPDATE","NEW")) -> CO | Z18: =_xlfn.XLOOKUP($B18,[1]F27!$C:$C,[1]F27!$BV:$BV) -> #ERROR! | AD18: =_xlfn.XLOOKUP($B18,[1]F27!$C:$C,[1]F27!$Y:$Y) -> #ERROR! | AE18: =_xlfn.XLOOKUP($B18,[1]F27!$C:$C,[1]F27!$Z:$Z) -> #ERROR! | AF18: =_xlfn.XLOOKUP($B18,[2]PRICING!$B:$B,[2]PRICING!$B:$B,"MISSING") -> #ERROR! | AG18: =COUNTIFS([2]ACTIVE_SCO!$B:$B,$B18,[2]ACTIVE_SCO!$P:$P,"Y") -> #ERROR! | AI18: FW28+ | AJ18: PLC: LS?? US-?? LSO-?? | AK18: Pre S23 | AL18: FW25 | AM18: Essentials | AN18: Active Essentials | AO18: Essentials | AS18: Insulation | AT18: Jacket | AU18: Midweight Synthetic | AV18: N | BA18: Pre S23 | BB18: FW25
A19: TRUE | B19: 608421 | C19: Chaos GTX II Jacket Men | D19: Apparel | G19: OUT | I19: Shell | J19: ABS | K19: Men | M19: TRUE | N19: FALSE | O19: 3500 | P19: 2.1 | Q19: 1666.67 | R19: 0.67878464 | S19: Good | U19: Gore-Tex | V19: None | X19: Intersport | Y19: =IF(M19=TRUE,"CO",IF(N19=TRUE,"UPDATE","NEW")) -> CO | Z19: =_xlfn.XLOOKUP($B19,[1]F27!$C:$C,[1]F27!$BV:$BV) -> #ERROR! | AD19: =_xlfn.XLOOKUP($B19,[1]F27!$C:$C,[1]F27!$Y:$Y) -> #ERROR! | AE19: =_xlfn.XLOOKUP($B19,[1]F27!$C:$C,[1]F27!$Z:$Z) -> #ERROR! | AF19: =_xlfn.XLOOKUP($B19,[2]PRICING!$B:$B,[2]PRICING!$B:$B,"MISSING") -> #ERROR! | AG19: =COUNTIFS([2]ACTIVE_SCO!$B:$B,$B19,[2]ACTIVE_SCO!$P:$P,"Y") -> #ERROR! | AI19: FW28+ | AJ19: PLC: LS?? US-?? LSO-?? | AK19: Pre S23 | AL19: SS25 | AM19: Outdoor | AN19: Active Essentials | AO19: Essentials | AS19: Shell | AT19: Jacket | AU19: 2L | AV19: Y | BA19: Pre S23 | BB19: SS25
A20: TRUE | B20: 608422 | C20: Chaos GTX II Jacket Women | D20: Apparel | G20: OUT | I20: Shell | J20: ABS | K20: Women | M20: TRUE | N20: FALSE | O20: 3500 | P20: 2.1 | Q20: 1666.67 | R20: 0.69681461 | S20: Good | U20: Gore-Tex | V20: None | X20: Intersport | Y20: =IF(M20=TRUE,"CO",IF(N20=TRUE,"UPDATE","NEW")) -> CO | Z20: =_xlfn.XLOOKUP($B20,[1]F27!$C:$C,[1]F27!$BV:$BV) -> #ERROR! | AD20: =_xlfn.XLOOKUP($B20,[1]F27!$C:$C,[1]F27!$Y:$Y) -> #ERROR! | AE20: =_xlfn.XLOOKUP($B20,[1]F27!$C:$C,[1]F27!$Z:$Z) -> #ERROR! | AF20: =_xlfn.XLOOKUP($B20,[2]PRICING!$B:$B,[2]PRICING!$B:$B,"MISSING") -> #ERROR! | AG20: =COUNTIFS([2]ACTIVE_SCO!$B:$B,$B20,[2]ACTIVE_SCO!$P:$P,"Y") -> #ERROR! | AI20: FW28+ | AJ20: PLC: LS?? US-?? LSO-?? | AK20: Pre S23 | AL20: SS25 | AM20: Outdoor | AN20: Active Essentials | AO20: Essentials | AS20: Shell | AT20: Jacket | AU20: 2L | AV20: Y | BA20: Pre S23 | BB20: SS25
A21: TRUE | B21: 605630 | C21: Chill Down Hood Men | D21: Apparel | G21: OUT | I21: Insulation | J21: ABS | K21: Men | M21: TRUE | N21: FALSE | O21: 3400 | P21: 2.1 | Q21: 1619.05 | R21: 0.59544177 | S21: Better | U21: Down | V21: None | X21: Intersport | Y21: =IF(M21=TRUE,"CO",IF(N21=TRUE,"UPDATE","NEW")) -> CO | Z21: =_xlfn.XLOOKUP($B21,[1]F27!$C:$C,[1]F27!$BV:$BV) -> #ERROR! | AD21: =_xlfn.XLOOKUP($B21,[1]F27!$C:$C,[1]F27!$Y:$Y) -> #ERROR! | AE21: =_xlfn.XLOOKUP($B21,[1]F27!$C:$C,[1]F27!$Z:$Z) -> #ERROR! | AF21: =_xlfn.XLOOKUP($B21,[2]PRICING!$B:$B,[2]PRICING!$B:$B,"MISSING") -> #ERROR! | AG21: =COUNTIFS([2]ACTIVE_SCO!$B:$B,$B21,[2]ACTIVE_SCO!$P:$P,"Y") -> #ERROR! | AI21: FW28+ | AJ21: PLC: LS?? US-?? LSO-?? | AK21: Pre S23 | AM21: Essentials | AN21: Active Essentials | AO21: Essentials | AS21: Insulation | AT21: Hooded Jacket | AU21: Midweight Down | AV21: N | BA21: Pre S23
A22: TRUE | B22: 608450 | C22: Fiction Down II Hood Men | D22: Apparel | G22: OUT | I22: Insulation | J22: ABS | K22: Men | M22: TRUE | N22: FALSE | O22: 2800 | P22: 2.1 | Q22: 1333.33 | R22: 0.65078413 | S22: Better | U22: Down | V22: None | X22: Intersport | Y22: =IF(M22=TRUE,"CO",IF(N22=TRUE,"UPDATE","NEW")) -> CO | Z22: =_xlfn.XLOOKUP($B22,[1]F27!$C:$C,[1]F27!$BV:$BV) -> #ERROR! | AD22: =_xlfn.XLOOKUP($B22,[1]F27!$C:$C,[1]F27!$Y:$Y) -> #ERROR! | AE22: =_xlfn.XLOOKUP($B22,[1]F27!$C:$C,[1]F27!$Z:$Z) -> #ERROR! | AF22: =_xlfn.XLOOKUP($B22,[2]PRICING!$B:$B,[2]PRICING!$B:$B,"MISSING") -> #ERROR! | AG22: =COUNTIFS([2]ACTIVE_SCO!$B:$B,$B22,[2]ACTIVE_SCO!$P:$P,"Y") -> #ERROR! | AI22: FW28+ | AJ22: PLC: LS?? US-?? LSO-?? | AK22: Pre S23 | AL22: FW25 | AM22: Essentials | AN22: Active Essentials | AO22: Essentials | AS22: Insulation | AT22: Hooded Jacket | AU22: Midweight Down | AV22: N | BA22: Pre S23 | BB22: FW25
A23: TRUE | B23: 608657 | C23: Aska Softshell Pant Men | D23: Apparel | G23: OUT | I23: Softshell | J23: ABS | K23: Men | M23: TRUE | N23: FALSE | O23: 1400 | P23: 2.1 | Q23: 666.67 | R23: 0.70483148 | S23: Good | U23: None | V23: None | X23: Intersport | Y23: =IF(M23=TRUE,"CO",IF(N23=TRUE,"UPDATE","NEW")) -> CO | Z23: =_xlfn.XLOOKUP($B23,[1]F27!$C:$C,[1]F27!$BV:$BV) -> #ERROR! | AD23: =_xlfn.XLOOKUP($B23,[1]F27!$C:$C,[1]F27!$Y:$Y) -> #ERROR! | AE23: =_xlfn.XLOOKUP($B23,[1]F27!$C:$C,[1]F27!$Z:$Z) -> #ERROR! | AF23: =_xlfn.XLOOKUP($B23,[2]PRICING!$B:$B,[2]PRICING!$B:$B,"MISSING") -> #ERROR! | AG23: =COUNTIFS([2]ACTIVE_SCO!$B:$B,$B23,[2]ACTIVE_SCO!$P:$P,"Y") -> #ERROR! | AI23: FW28+ | AJ23: PLC: LS?? US-?? LSO-?? | AK23: SS27 | AM23: Outdoor | AN23: Day Hiking | AO23: Outdoor | AP23: Hiking | AS23: Softshell | AT23: Pant | AU23: Classic Softshell | AV23: N | AY23: Trekking? | BA23: SS27
A24: TRUE | B24: 608659 | C24: Aska Softshell Pant Women | D24: Apparel | G24: OUT | I24: Softshell | J24: ABS | K24: Women | M24: TRUE | N24: FALSE | O24: 1400 | P24: 2.1 | Q24: 666.67 | R24: 0.71021645 | S24: Good | U24: None | V24: None | X24: Intersport | Y24: =IF(M24=TRUE,"CO",IF(N24=TRUE,"UPDATE","NEW")) -> CO | Z24: =_xlfn.XLOOKUP($B24,[1]F27!$C:$C,[1]F27!$BV:$BV) -> #ERROR! | AD24: =_xlfn.XLOOKUP($B24,[1]F27!$C:$C,[1]F27!$Y:$Y) -> #ERROR! | AE24: =_xlfn.XLOOKUP($B24,[1]F27!$C:$C,[1]F27!$Z:$Z) -> #ERROR! | AF24: =_xlfn.XLOOKUP($B24,[2]PRICING!$B:$B,[2]PRICING!$B:$B,"MISSING") -> #ERROR! | AG24: =COUNTIFS([2]ACTIVE_SCO!$B:$B,$B24,[2]ACTIVE_SCO!$P:$P,"Y") -> #ERROR! | AI24: FW28+ | AJ24: PLC: LS?? US-?? LSO-?? | AK24: SS27 | AM24: Outdoor | AN24: Day Hiking | AO24: Outdoor | AP24: Hiking | AS24: Softshell | AT24: Pant | AU24: Classic Softshell | AV24: N | AY24: Trekking? | BA24: SS27
A25: TRUE | B25: 608527 | C25: Pollux 1/2 zip II Jacket Men | D25: Apparel | G25: OUT | I25: Midlayer | J25: ABS | K25: Men | M25: TRUE | N25: FALSE | O25: 800 | P25: 2.1 | Q25: 380.95 | R25: 0.59574747 | S25: Good | U25: Polartec | V25: None | X25: XXL | Y25: =IF(M25=TRUE,"CO",IF(N25=TRUE,"UPDATE","NEW")) -> CO | Z25: =_xlfn.XLOOKUP($B25,[1]F27!$C:$C,[1]F27!$BV:$BV) -> #ERROR! | AD25: =_xlfn.XLOOKUP($B25,[1]F27!$C:$C,[1]F27!$Y:$Y) -> #ERROR! | AE25: =_xlfn.XLOOKUP($B25,[1]F27!$C:$C,[1]F27!$Z:$Z) -> #ERROR! | AF25: =_xlfn.XLOOKUP($B25,[2]PRICING!$B:$B,[2]PRICING!$B:$B,"MISSING") -> #ERROR! | AG25: =COUNTIFS([2]ACTIVE_SCO!$B:$B,$B25,[2]ACTIVE_SCO!$P:$P,"Y") -> #ERROR! | AI25: FW27 or SS28 | AJ25: Replaced with Buteo 1/2 zip Inline | AK25: Pre S23 | AL25: FW26 | AM25: Essentials | AN25: Active Essentials | AO25: Essentials | AS25: Fleece/Midlayer | AT25: 1/2 Zip | AU25: Lightweight | AV25: N | BA25: Pre S23 | BB25: FW26
A26: TRUE | B26: 608528 | C26: Pollux 1/2 zip II Jacket Women | D26: Apparel | G26: OUT | I26: Midlayer | J26: ABS | K26: Women | M26: TRUE | N26: FALSE | O26: 800 | P26: 2.1 | Q26: 380.95 | R26: 0.62955768 | S26: Good | U26: Polartec | V26: None | X26: XXL | Y26: =IF(M26=TRUE,"CO",IF(N26=TRUE,"UPDATE","NEW")) -> CO | Z26: =_xlfn.XLOOKUP($B26,[1]F27!$C:$C,[1]F27!$BV:$BV) -> #ERROR! | AD26: =_xlfn.XLOOKUP($B26,[1]F27!$C:$C,[1]F27!$Y:$Y) -> #ERROR! | AE26: =_xlfn.XLOOKUP($B26,[1]F27!$C:$C,[1]F27!$Z:$Z) -> #ERROR! | AF26: =_xlfn.XLOOKUP($B26,[2]PRICING!$B:$B,[2]PRICING!$B:$B,"MISSING") -> #ERROR! | AG26: =COUNTIFS([2]ACTIVE_SCO!$B:$B,$B26,[2]ACTIVE_SCO!$P:$P,"Y") -> #ERROR! | AI26: FW28+ | AJ26: Replaced with Buteo 1/2 zip Inline | AK26: Pre S23 | AL26: FW26 | AM26: Essentials | AN26: Active Essentials | AO26: Essentials | AS26: Fleece/Midlayer | AT26: 1/2 Zip | AU26: Lightweight | AV26: N | BA26: Pre S23 | BB26: FW26
A27: TRUE | B27: 608864 | C27: Skuta Proof Jacket Men | D27: Apparel | G27: OUT | I27: Shell | J27: ABS | K27: Men | M27: FALSE | N27: FALSE | O27: 2500 | P27: 2.1 | Q27: 1190.48 | R27: 0.70470734 | S27: Good | U27: Proof | V27: None | Y27: =IF(M27=TRUE,"CO",IF(N27=TRUE,"UPDATE","NEW")) -> NEW | Z27: =_xlfn.XLOOKUP($B27,[1]F27!$C:$C,[1]F27!$BV:$BV) -> #ERROR! | AD27: =_xlfn.XLOOKUP($B27,[1]F27!$C:$C,[1]F27!$Y:$Y) -> #ERROR! | AE27: =_xlfn.XLOOKUP($B27,[1]F27!$C:$C,[1]F27!$Z:$Z) -> #ERROR! | AF27: =_xlfn.XLOOKUP($B27,[2]PRICING!$B:$B,[2]PRICING!$B:$B,"MISSING") -> #ERROR! | AG27: =COUNTIFS([2]ACTIVE_SCO!$B:$B,$B27,[2]ACTIVE_SCO!$P:$P,"Y") -> #ERROR! | AI27: FW28+ | AJ27: PLC: LS?? US-?? LSO-?? | AK27: SS27 | AM27: Essentials | AN27: Active Essentials | AO27: Essentials | AS27: Shell | AT27: Jacket | AU27: 2L | AV27: Y | BA27: SS27
A28: TRUE | B28: 608863 | C28: Skuta Proof Jacket Women | D28: Apparel | G28: OUT | I28: Shell | J28: ABS | K28: Women | M28: FALSE | N28: FALSE | O28: 2500 | P28: 2.1 | Q28: 1190.48 | R28: 0.72132249 | S28: Good | U28: Proof | V28: None | Y28: =IF(M28=TRUE,"CO",IF(N28=TRUE,"UPDATE","NEW")) -> NEW | Z28: =_xlfn.XLOOKUP($B28,[1]F27!$C:$C,[1]F27!$BV:$BV) -> #ERROR! | AD28: =_xlfn.XLOOKUP($B28,[1]F27!$C:$C,[1]F27!$Y:$Y) -> #ERROR! | AE28: =_xlfn.XLOOKUP($B28,[1]F27!$C:$C,[1]F27!$Z:$Z) -> #ERROR! | AF28: =_xlfn.XLOOKUP($B28,[2]PRICING!$B:$B,[2]PRICING!$B:$B,"MISSING") -> #ERROR! | AG28: =COUNTIFS([2]ACTIVE_SCO!$B:$B,$B28,[2]ACTIVE_SCO!$P:$P,"Y") -> #ERROR! | AI28: FW28+ | AJ28: PLC: LS?? US-?? LSO-?? | AK28: SS27 | AM28: Essentials | AN28: Active Essentials | AO28: Essentials | AS28: Shell | AT28: Jacket | AU28: 2L | AV28: Y | BA28: SS27
A29: TRUE | B29: 607855 | C29: Trekk Tech LS Tee Men | D29: Apparel | G29: OUT | I29: Tops | J29: ABS | K29: Men | M29: TRUE | N29: FALSE | O29: 700 | P29: 2.1 | Q29: 333.33 | R29: 0.74373744 | S29: Good | U29: None | V29: None | Y29: =IF(M29=TRUE,"CO",IF(N29=TRUE,"UPDATE","NEW")) -> CO | Z29: =_xlfn.XLOOKUP($B29,[1]F27!$C:$C,[1]F27!$BV:$BV) -> #ERROR! | AD29: =_xlfn.XLOOKUP($B29,[1]F27!$C:$C,[1]F27!$Y:$Y) -> #ERROR! | AE29: =_xlfn.XLOOKUP($B29,[1]F27!$C:$C,[1]F27!$Z:$Z) -> #ERROR! | AF29: =_xlfn.XLOOKUP($B29,[2]PRICING!$B:$B,[2]PRICING!$B:$B,"MISSING") -> #ERROR! | AG29: =COUNTIFS([2]ACTIVE_SCO!$B:$B,$B29,[2]ACTIVE_SCO!$P:$P,"Y") -> #ERROR! | AI29: FW27 | AJ29: PLC: LS?? US LSO-FW27 | AK29: Pre S23 | AL29: SS25 | AM29: Essentials | AN29: Active Essentials | AO29: Essentials | AQ29: Essentials | AS29: Tops | AT29: Tee | AU29: Tech Tee | AV29: N | BA29: Pre S23 | BB29: SS25
A30: TRUE | B30: 607858 | C30: Trekk Tech LS Tee Women | D30: Apparel | G30: OUT | I30: Tops | J30: ABS | K30: Women | M30: TRUE | N30: FALSE | O30: 700 | P30: 2.1 | Q30: 333.33 | R30: 0.76824768 | S30: Good | U30: None | V30: None | Y30: =IF(M30=TRUE,"CO",IF(N30=TRUE,"UPDATE","NEW")) -> CO | Z30: =_xlfn.XLOOKUP($B30,[1]F27!$C:$C,[1]F27!$BV:$BV) -> #ERROR! | AD30: =_xlfn.XLOOKUP($B30,[1]F27!$C:$C,[1]F27!$Y:$Y) -> #ERROR! | AE30: =_xlfn.XLOOKUP($B30,[1]F27!$C:$C,[1]F27!$Z:$Z) -> #ERROR! | AF30: =_xlfn.XLOOKUP($B30,[2]PRICING!$B:$B,[2]PRICING!$B:$B,"MISSING") -> #ERROR! | AG30: =COUNTIFS([2]ACTIVE_SCO!$B:$B,$B30,[2]ACTIVE_SCO!$P:$P,"Y") -> #ERROR! | AI30: FW27 | AJ30: PLC: LS?? US LSO-FW27 | AK30: Pre S23 | AL30: SS25 | AM30: Essentials | AN30: Active Essentials | AO30: Essentials | AQ30: Essentials | AS30: Tops | AT30: Tee | AU30: Tech Tee | AV30: N | BA30: Pre S23 | BB30: SS25
A31: TRUE | B31: 607856 | C31: Trekk Tech Tee Men | D31: Apparel | G31: OUT | I31: Tops | J31: ABS | K31: Men | M31: TRUE | N31: FALSE | O31: 500 | P31: 2.1 | Q31: 238.1 | R31: 0.69252415 | S31: Good | U31: None | V31: None | Y31: =IF(M31=TRUE,"CO",IF(N31=TRUE,"UPDATE","NEW")) -> CO | Z31: =_xlfn.XLOOKUP($B31,[1]F27!$C:$C,[1]F27!$BV:$BV) -> #ERROR! | AD31: =_xlfn.XLOOKUP($B31,[1]F27!$C:$C,[1]F27!$Y:$Y) -> #ERROR! | AE31: =_xlfn.XLOOKUP($B31,[1]F27!$C:$C,[1]F27!$Z:$Z) -> #ERROR! | AF31: =_xlfn.XLOOKUP($B31,[2]PRICING!$B:$B,[2]PRICING!$B:$B,"MISSING") -> #ERROR! | AG31: =COUNTIFS([2]ACTIVE_SCO!$B:$B,$B31,[2]ACTIVE_SCO!$P:$P,"Y") -> #ERROR! | AI31: FW27 | AJ31: PLC: LS?? US LSO-FW27 | AK31: Pre S23 | AL31: SS25 | AM31: Essentials | AN31: Active Essentials | AO31: Essentials | AQ31: Essentials | AS31: Tops | AT31: Tee | AU31: Tech Tee | AV31: N | BA31: Pre S23 | BB31: SS25
A32: TRUE | B32: 607857 | C32: Trekk Tech Tee Women | D32: Apparel | G32: OUT | I32: Tops | J32: ABS | K32: Women | M32: TRUE | N32: FALSE | O32: 500 | P32: 2.1 | Q32: 238.1 | R32: 0.70949181 | S32: Good | U32: None | V32: None | Y32: =IF(M32=TRUE,"CO",IF(N32=TRUE,"UPDATE","NEW")) -> CO | Z32: =_xlfn.XLOOKUP($B32,[1]F27!$C:$C,[1]F27!$BV:$BV) -> #ERROR! | AD32: =_xlfn.XLOOKUP($B32,[1]F27!$C:$C,[1]F27!$Y:$Y) -> #ERROR! | AE32: =_xlfn.XLOOKUP($B32,[1]F27!$C:$C,[1]F27!$Z:$Z) -> #ERROR! | AF32: =_xlfn.XLOOKUP($B32,[2]PRICING!$B:$B,[2]PRICING!$B:$B,"MISSING") -> #ERROR! | AG32: =COUNTIFS([2]ACTIVE_SCO!$B:$B,$B32,[2]ACTIVE_SCO!$P:$P,"Y") -> #ERROR! | AI32: FW27 | AJ32: PLC: LS?? US LSO-FW27 | AK32: Pre S23 | AL32: SS25 | AM32: Essentials | AN32: Active Essentials | AO32: Essentials | AQ32: Essentials | AS32: Tops | AT32: Tee | AU32: Tech Tee | AV32: N | BA32: Pre S23 | BB32: SS25
A33: TRUE | B33: 608874 | C33: Steep GTX Jacket Men | D33: Apparel | G33: OUT | I33: Shell | J33: ABS | K33: Men | M33: FALSE | N33: FALSE | O33: 4000 | P33: 2.1 | Q33: 1904.76 | R33: 0.56852307 | S33: Better | U33: Gore-Tex | V33: None | Y33: =IF(M33=TRUE,"CO",IF(N33=TRUE,"UPDATE","NEW")) -> NEW | Z33: =_xlfn.XLOOKUP($B33,[1]F27!$C:$C,[1]F27!$BV:$BV) -> #ERROR! | AD33: =_xlfn.XLOOKUP($B33,[1]F27!$C:$C,[1]F27!$Y:$Y) -> #ERROR! | AE33: =_xlfn.XLOOKUP($B33,[1]F27!$C:$C,[1]F27!$Z:$Z) -> #ERROR! | AF33: =_xlfn.XLOOKUP($B33,[2]PRICING!$B:$B,[2]PRICING!$B:$B,"MISSING") -> #ERROR! | AG33: =COUNTIFS([2]ACTIVE_SCO!$B:$B,$B33,[2]ACTIVE_SCO!$P:$P,"Y") -> #ERROR! | AI33: FW28+ | AJ33: PLC: LS?? US-?? LSO-?? | AK33: SS27 | AM33: Essentials | AN33: Active Essentials | AO33: Essentials | AS33: Shell | AT33: Jacket | AU33: 2L | AV33: Y | BA33: SS27
A34: TRUE | B34: 608873 | C34: Steep GTX Jacket Women | D34: Apparel | G34: OUT | I34: Shell | J34: ABS | K34: Women | M34: FALSE | N34: FALSE | O34: 4000 | P34: 2.1 | Q34: 1904.76 | R34: 0.59499359 | S34: Better | U34: Gore-Tex | V34: None | Y34: =IF(M34=TRUE,"CO",IF(N34=TRUE,"UPDATE","NEW")) -> NEW | Z34: =_xlfn.XLOOKUP($B34,[1]F27!$C:$C,[1]F27!$BV:$BV) -> #ERROR! | AD34: =_xlfn.XLOOKUP($B34,[1]F27!$C:$C,[1]F27!$Y:$Y) -> #ERROR! | AE34: =_xlfn.XLOOKUP($B34,[1]F27!$C:$C,[1]F27!$Z:$Z) -> #ERROR! | AF34: =_xlfn.XLOOKUP($B34,[2]PRICING!$B:$B,[2]PRICING!$B:$B,"MISSING") -> #ERROR! | AG34: =COUNTIFS([2]ACTIVE_SCO!$B:$B,$B34,[2]ACTIVE_SCO!$P:$P,"Y") -> #ERROR! | AI34: FW28+ | AJ34: PLC: LS?? US-?? LSO-?? | AK34: SS27 | AM34: Essentials | AN34: Active Essentials | AO34: Essentials | AS34: Shell | AT34: Jacket | AU34: 2L | AV34: Y | BA34: SS27
A35: FALSE | B35: 608256 | C35: Bield Down II Hood Men | D35: Apparel | G35: OUT | I35: Insulation | J35: ABS | K35: Men | M35: TRUE | N35: FALSE | O35: 2700 | P35: 2.1 | Q35: 1285.71 | R35: 0.64038547 | S35: Better | U35: Down | V35: None | X35: XXL | Y35: =IF(M35=TRUE,"CO",IF(N35=TRUE,"UPDATE","NEW")) -> CO | Z35: =_xlfn.XLOOKUP($B35,[1]F27!$C:$C,[1]F27!$BV:$BV) -> #ERROR! | AD35: =_xlfn.XLOOKUP($B35,[1]F27!$C:$C,[1]F27!$Y:$Y) -> #ERROR! | AE35: =_xlfn.XLOOKUP($B35,[1]F27!$C:$C,[1]F27!$Z:$Z) -> #ERROR! | AF35: =_xlfn.XLOOKUP($B35,[2]PRICING!$B:$B,[2]PRICING!$B:$B,"MISSING") -> #ERROR! | AG35: =COUNTIFS([2]ACTIVE_SCO!$B:$B,$B35,[2]ACTIVE_SCO!$P:$P,"Y") -> #ERROR! | AI35: REVIEW
A36: FALSE | B36: 608257 | C36: Bield Down II Hood Women | D36: Apparel | G36: OUT | I36: Insulation | J36: ABS | K36: Women | M36: TRUE | N36: FALSE | O36: 2700 | P36: 2.1 | Q36: 1285.71 | R36: 0.6798656 | S36: Better | U36: Down | V36: None | X36: XXL | Y36: =IF(M36=TRUE,"CO",IF(N36=TRUE,"UPDATE","NEW")) -> CO | Z36: =_xlfn.XLOOKUP($B36,[1]F27!$C:$C,[1]F27!$BV:$BV) -> #ERROR! | AD36: =_xlfn.XLOOKUP($B36,[1]F27!$C:$C,[1]F27!$Y:$Y) -> #ERROR! | AE36: =_xlfn.XLOOKUP($B36,[1]F27!$C:$C,[1]F27!$Z:$Z) -> #ERROR! | AF36: =_xlfn.XLOOKUP($B36,[2]PRICING!$B:$B,[2]PRICING!$B:$B,"MISSING") -> #ERROR! | AG36: =COUNTIFS([2]ACTIVE_SCO!$B:$B,$B36,[2]ACTIVE_SCO!$P:$P,"Y") -> #ERROR! | AI36: REVIEW
A37: TRUE | B37: 608872 | C37: Zircon Flex Pant Men | D37: Apparel | G37: OUT | I37: Legwear | J37: ABS | K37: Men | M37: FALSE | N37: FALSE | O37: 2000 | P37: 2.1 | Q37: 952.38 | R37: 0.6956992 | S37: Better | U37: None | V37: None | Y37: =IF(M37=TRUE,"CO",IF(N37=TRUE,"UPDATE","NEW")) -> NEW | Z37: =_xlfn.XLOOKUP($B37,[1]F27!$C:$C,[1]F27!$BV:$BV) -> #ERROR! | AD37: =_xlfn.XLOOKUP($B37,[1]F27!$C:$C,[1]F27!$Y:$Y) -> #ERROR! | AE37: =_xlfn.XLOOKUP($B37,[1]F27!$C:$C,[1]F27!$Z:$Z) -> #ERROR! | AF37: =_xlfn.XLOOKUP($B37,[2]PRICING!$B:$B,[2]PRICING!$B:$B,"MISSING") -> #ERROR! | AG37: =COUNTIFS([2]ACTIVE_SCO!$B:$B,$B37,[2]ACTIVE_SCO!$P:$P,"Y") -> #ERROR! | AI37: FW28+ | AJ37: PLC: LS?? US-?? LSO-?? | AK37: SS27 | AM37: Outdoor | AN37: Day Hiking | AO37: Outdoor | AP37: Hiking | AS37: Legwear | AT37: Pant | AU37: Classic Softshell | AV37: N | BA37: SS27
A38: TRUE | B38: 608871 | C38: Zircon Flex Pant Women | D38: Apparel | G38: OUT | I38: Legwear | J38: ABS | K38: Women | M38: FALSE | N38: FALSE | O38: 2000 | P38: 2.1 | Q38: 952.38 | R38: 0.6973792 | S38: Better | U38: None | V38: None | Y38: =IF(M38=TRUE,"CO",IF(N38=TRUE,"UPDATE","NEW")) -> NEW | Z38: =_xlfn.XLOOKUP($B38,[1]F27!$C:$C,[1]F27!$BV:$BV) -> #ERROR! | AD38: =_xlfn.XLOOKUP($B38,[1]F27!$C:$C,[1]F27!$Y:$Y) -> #ERROR! | AE38: =_xlfn.XLOOKUP($B38,[1]F27!$C:$C,[1]F27!$Z:$Z) -> #ERROR! | AF38: =_xlfn.XLOOKUP($B38,[2]PRICING!$B:$B,[2]PRICING!$B:$B,"MISSING") -> #ERROR! | AG38: =COUNTIFS([2]ACTIVE_SCO!$B:$B,$B38,[2]ACTIVE_SCO!$P:$P,"Y") -> #ERROR! | AI38: FW28+ | AJ38: PLC: LS?? US-?? LSO-?? | AK38: SS27 | AM38: Outdoor | AN38: Day Hiking | AO38: Outdoor | AP38: Hiking | AS38: Legwear | AT38: Pant | AU38: Classic Softshell | AV38: N | BA38: SS27
A39: TRUE | B39: 608639 | C39: Zodiac Mid II Jacket Men | D39: Apparel | G39: OUT | I39: Midlayer | J39: ABS | K39: Men | M39: TRUE | N39: FALSE | O39: 1300 | P39: 2.1 | Q39: 619.05 | R39: 0.62762297 | S39: Good | U39: None | V39: None | X39: XXL | Y39: =IF(M39=TRUE,"CO",IF(N39=TRUE,"UPDATE","NEW")) -> CO | Z39: =_xlfn.XLOOKUP($B39,[1]F27!$C:$C,[1]F27!$BV:$BV) -> #ERROR! | AD39: =_xlfn.XLOOKUP($B39,[1]F27!$C:$C,[1]F27!$Y:$Y) -> #ERROR! | AE39: =_xlfn.XLOOKUP($B39,[1]F27!$C:$C,[1]F27!$Z:$Z) -> #ERROR! | AF39: =_xlfn.XLOOKUP($B39,[2]PRICING!$B:$B,[2]PRICING!$B:$B,"MISSING") -> #ERROR! | AG39: =COUNTIFS([2]ACTIVE_SCO!$B:$B,$B39,[2]ACTIVE_SCO!$P:$P,"Y") -> #ERROR! | AI39: FW28+ | AJ39: STILL OFFERING THIS ABS PAST FW27? | AK39: SS25 | AL39: SS27 | AM39: Essentials | AN39: Active Essentials | AO39: Essentials | AS39: Fleece/Midlayer | AT39: Jacket | AU39: Midweight | AV39: N | BA39: SS25 | BB39: SS27
A40: TRUE | B40: 608640 | C40: Zodiac Mid II Jacket Women | D40: Apparel | G40: OUT | I40: Midlayer | J40: ABS | K40: Women | M40: TRUE | N40: FALSE | O40: 1300 | P40: 2.1 | Q40: 619.05 | R40: 0.65182134 | S40: Good | U40: None | V40: None | X40: XXL | Y40: =IF(M40=TRUE,"CO",IF(N40=TRUE,"UPDATE","NEW")) -> CO | Z40: =_xlfn.XLOOKUP($B40,[1]F27!$C:$C,[1]F27!$BV:$BV) -> #ERROR! | AD40: =_xlfn.XLOOKUP($B40,[1]F27!$C:$C,[1]F27!$Y:$Y) -> #ERROR! | AE40: =_xlfn.XLOOKUP($B40,[1]F27!$C:$C,[1]F27!$Z:$Z) -> #ERROR! | AF40: =_xlfn.XLOOKUP($B40,[2]PRICING!$B:$B,[2]PRICING!$B:$B,"MISSING") -> #ERROR! | AG40: =COUNTIFS([2]ACTIVE_SCO!$B:$B,$B40,[2]ACTIVE_SCO!$P:$P,"Y") -> #ERROR! | AI40: FW28+ | AJ40: STILL OFFERING THIS ABS PAST FW27? | AK40: SS25 | AL40: SS27 | AM40: Essentials | AN40: Active Essentials | AO40: Essentials | AS40: Fleece/Midlayer | AT40: Jacket | AU40: Midweight | AV40: N | BA40: SS25 | BB40: SS27
...

Sheet SS28
A2: Season | B2: Style Seasonality | C2: Active | D2: Code | E2: Style | F2: xx | G2: Business Area | H2: CO Seson | I2: Status | J2: Tobias Comment | K2: Merch Comment | L2: Other | M2: Product Concept | N2: Category/Layer | O2: Collection Type | P2: Gender | Q2: Product Type | R2: Type | S2: xxx | T2: xxxx | U2: RRP Comment | V2: Target RRP | W2: Mark-up | X2: WP | Y2: DISCOUNT | Z2: NET PRICE | AA2: GM0% | AB2: Product Hierarchy | AC2: Target GM0% | AD2: Actual LC SEK | AE2: Main technology platform | AF2: Secondary technology platform | AG2: Target No. of SCO | AH2: Actual No. Of SCO | AI2: Style Comment | AJ2: ABS Customer | AK2: FORECAST 0 | AL2: S27 | AM2: S26 | AN2: F27 | AO2: F26 | AP2: FORECAST 0 | AQ2: S27 | AR2: F26 | AS2: S28 | AT2: F26 | AU2: FORECAST 0 | AV2: S27 | AW2: S26 | AX2: F27 | AY2: F26 | AZ2: Info & Comments | BA2: Collection | BB2: NEW MAPPING: Activity | BC2: PPT Collection / Activity (deck) | BD2: Category/Layer(V2) | BE2: Silhouette | BF2: Category/Layer Subtype | BG2: Waterproof | BH2: Attribution Review | BI2: Franchise/Family | BJ2: Note
A3: SS28 | C3: FALSE | D3: 608822 | E3: Airak GTX Prototype Jacket Men | G3: Apparel | H3: F27 | I3: CANCELED | J3: Seasonal Brand Builder | M3: L.I.M | N3: Shell | O3: ABS Exclusive | P3: Men | Q3: Jacket | R3: Top | V3: 0 | W3: 2.1 | X3: 0 | Y3: 0 | Z3: 0 | AA3: 0 | AE3: Gore-Tex | AH3: 1 | AJ3: KA YO Collab | AL3: 0 | AM3: 0 | AN3: 0 | AO3: 0 | AP3: 0 | AQ3: 0 | AR3: 0 | AS3: 0 | AT3: 0 | AU3: 0 | AV3: 0 | AW3: 0 | AX3: 0 | AY3: 0 | AZ3: NOT Active in Centric | BA3: Essentials | BB3: Active Essentials | BD3: Shell | BE3: Jacket | BF3: 3L | BG3: Y
A4: SS28 | B4: All year | C4: TRUE | D4: 608172 | E4: Alert GTX Jacket Men | G4: Apparel | H4: F27 | I4: CO | M4: OUT | N4: Shell | O4: Inline | P4: Men | Q4: Jacket | R4: Top | V4: 3800 | W4: 2.1 | X4: 1810 | Y4: 0.2 | Z4: 1448 | AA4: 1 | AB4: Good | AC4: 0.58 | AE4: Gore-Tex | AF4: None | AG4: 4 | AH4: 4 | AI4: potentially add 1 new. Charlotte: 4SCO. 1 NEW. | AK4: 1700 | AL4: 1653 | AM4: 1630 | AN4: 1330 | AO4: 861 | AP4: 3077000 | AQ4: 2991136.6 | AR4: 1558410 | AS4: 0 | AT4: 1558410 | AU4: 2461600 | AV4: 2537969 | AW4: 2396467.4 | AX4: 1980693.6 | AY4: 1353722.4 | BA4: Outdoor | BB4: Day Hiking | BC4: Outdoor / Hiking [MATCH] | BD4: Shell | BE4: Jacket | BF4: 2L | BG4: Y
A5: SS28 | B5: All year | C5: TRUE | D5: 608596 | E5: Alert GTX Jacket Men AF | G5: Apparel | H5: F27 | I5: CO | J5: Asia Fit | M5: OUT | N5: Shell | O5: ABS Exclusive | P5: Men | Q5: Jacket | R5: Top | V5: 3800 | W5: 2.1 | X5: 1810 | Y5: 0.2 | Z5: 1448 | AA5: 1 | AB5: Good | AE5: Gore-Tex | AF5: None | AH5: 0 | AI5: follow inline. Charlotte: 4SCO. 1 New. | AJ5: ASIA | AK5: 1000 | AL5: 1000 | AM5: 1000 | AN5: 300 | AO5: 0 | AP5: 1810000 | AQ5: 1809520 | AR5: 0 | AS5: 0 | AT5: 0 | AU5: 1448000 | AV5: 633410 | AW5: 669600 | AX5: 190023 | AY5: 0 | AZ5: NOT Active in Centric | BA5: Outdoor | BB5: Day Hiking | BC5: Outdoor / Hiking [MATCH] | BD5: Shell | BE5: Jacket | BF5: 2L | BG5: Y
A6: SS28 | B6: All year | C6: TRUE | D6: 608192 | E6: Alert GTX Jacket Women | G6: Apparel | H6: F27 | I6: CO | M6: OUT | N6: Shell | O6: Inline | P6: Women | Q6: Jacket | R6: Top | V6: 3800 | W6: 2.1 | X6: 1810 | Y6: 0.2 | Z6: 1448 | AA6: 1 | AB6: Good | AC6: 0.6 | AE6: Gore-Tex | AF6: None | AG6: 4 | AH6: 4 | AI6: potentially add 1 new if LT Haze Blue does not work in a FW. Charlotte: 4SCO. 1 New. | AK6: 2000 | AL6: 1989 | AM6: 1878 | AN6: 1239 | AO6: 521 | AP6: 3620000 | AQ6: 3599135.3 | AR6: 943010 | AS6: 0 | AT6: 943010 | AU6: 2896000 | AV6: 2645230.1 | AW6: 2194639.4 | AX6: 1663577.9 | AY6: 831871.75 | BA6: Outdoor | BB6: Day Hiking | BC6: Outdoor / Hiking [MATCH] | BD6: Shell | BE6: Jacket | BF6: 2L | BG6: Y
A7: SS28 | B7: All year | C7: TRUE | D7: 607645 | E7: Alert Mid Pant Men | G7: Apparel | H7: F27 | I7: CO | M7: OUT | N7: Legwear | O7: Inline | P7: Men | Q7: Pants | R7: Bottom | V7: 1700 | W7: 2.1 | X7: 810 | Y7: 0.2 | Z7: 648 | AA7: 1 | AB7: Better | AC7: 0.62 | AE7: None | AF7: None | AG7: 4 | AH7: 4 | AI7: 4SCO. No new. Update FW28? | AK7: 6000 | AL7: 7095 | AM7: 4652 | AN7: 5683 | AO7: 4400 | AP7: 4860000 | AQ7: 5743544.4 | AR7: 3564000 | AS7: 0 | AT7: 3564000 | AU7: 3888000 | AV7: 4637409.9 | AW7: 2901739.1 | AX7: 3512969.7 | AY7: 2723876.7 | BA7: Outdoor | BB7: Trekking | BC7: Outdoor / Mountaineering [CHECK - activity] | BD7: Softshell | BE7: Pant | BF7: Classic Softshell | BG7: N
